#VRML_SIM R2019a utf8
WorldInfo {
}
Viewpoint {
  orientation 0.3204209897144308 -0.915129670598964 -0.24467953600547881 4.91768090834141
  position 0.9948947563913724 0.8802064507671239 0.11181578693506476
}
TexturedBackground {
}
TexturedBackgroundLight {
}
Floor {
}
Solid {
  translation -0.025451858919455006 0.25 -0.020639252879159242
  children [
    Shape {
      appearance PBRAppearance {
        baseColor 0 0 1
        roughness 1
      }
      geometry Cylinder {
        height 0.5
        radius 0.03
      }
    }
    HingeJoint {
      jointParameters HingeJointParameters {
        position 0.14563346241576455
        axis 0 1 0
        anchor 0 0.225 0
        minStop -0.785
        maxStop 0.785
        dampingConstant 0.2
        staticFriction 0.01
      }
      endPoint Solid {
        translation -2.7965256575063724e-17 0.25498431953667233 5.951476384915461e-19
        rotation -1.5528747514193607e-22 1 3.010383928189711e-21 0.14563346241576533
        children [
          Shape {
            appearance PBRAppearance {
              baseColor 1 0 0
              roughness 1
            }
            geometry Box {
              size 0.8 0.01 0.1
            }
          }
        ]
        physics Physics {
        }
      }
    }
    HingeJoint {
      jointParameters HingeJointParameters {
        axis 0 0 1
        anchor 0 0 -0.035
      }
      endPoint Solid {
        translation 0 -1.5680463327616412e-05 -0.035
        children [
          Shape {
            appearance PBRAppearance {
              baseColor 0 1 0
              roughness 1
            }
            geometry Box {
              size 0.1 0.03 0.01
            }
          }
        ]
        name "solid(1)"
        physics Physics {
        }
      }
    }
  ]
}
